Workbook

Sheet Questionário
C3: Questionário de Avaliação de fornecedor Segurança da Informação
B5: Informações gerais do fornecedor
B6: Informações gerais:
B7: Nome do Fornecedor:
B8: CNPJ do Fornecedor:
B9: Data do Preenchimento:
B10: Endereço da Empresa:
B11: Responsável pelo preenchimento:
B12: Cargo e área do responsável pelo preenchimento:
B14: Informações sobre o serviço a ser prestado pelo Fornecedor
B15: # | C15: Questão | D15: Resposta
B16: 1 | C16: Qual é a funcionalidade da ferramenta/sistema?
B17: 3 | C17: Infraestrutura BS2 ou Terceira?
B18: 4 | C18: O serviço será prestado de forma contínua, sob demanda ou em projetos pontuais?
B20: Avaliação de relevância do fornecedor
C21: Fornecedor Relevante | D21: Avaliação geral | F21: Avaliação SI
D22: =IF(OR(E24="Relevante", E25="Relevante",E26="Relevante",E27="Relevante",E28="Relevante"),"Relevante","N/A Relevante") -> N/A Relevante | F22: =IF(OR(G24="Relevante", G25="Relevante",G26="Relevante",G27="Relevante",G28="Relevante"),"Relevante","N/A Relevante") -> N/A Relevante
B23: # | C23: Questão | D23: Resposta | E23: Resultado | F23: Resposta | G23: Resultado SI | H23: Explanação
B24: 1 | C24: O fornecedor irá processar ou armazenar dados sensíveis em nuvem? Quais? Em qual região serão armazenados? | E24: =IF(D24="Sim","Relevante","Não Relevante") -> Não Relevante | G24: =IF(F24="Sim","Relevante","Não Relevante") -> Não Relevante
B25: 2 | C25: A descontinuidade momentânea do fornecedor afeta significativamente algum processo ou serviço das empresas BS2 ? | E25: =IF(D25="Sim","Relevante","Não Relevante") -> Não Relevante | G25: =IF(F25="Sim","Relevante","Não Relevante") -> Não Relevante
B26: 3 | C26: Os serviços/ sistemas fornecidos pelo terceiro, contemplam áreas e/ ou processos críticos? | E26: =IF(D26="Sim","Relevante","Não Relevante") -> Não Relevante | G26: =IF(F26="Sim","Relevante","Não Relevante") -> Não Relevante
B27: 4 | C27: O serviço/ sistema está vinculado aos produtos/negócios mais rentáveis para as empresas BS2 ? | E27: =IF(D27="Sim","Relevante","Não Relevante") -> Não Relevante | G27: =IF(F27="Sim","Relevante","Não Relevante") -> Não Relevante
B28: 5 | C28: Valor do contrato é relevante (valores totais pagos acima de R$ 100 mil/mês, por exemplo)? | E28: =IF(D28="Sim","Relevante","Não Relevante") -> Não Relevante | G28: =IF(F28="Sim","Relevante","Não Relevante") -> Não Relevante
B30: Fornecedor - Sobre a estrutura de SI:
B31: Obs.: Essas questões devem ser respondidas com base na estrutura da empresa do fornecedor a ser contratado ou serviço a ser contratada.
B33: 1. Privacidade de Dados | E33: =SUM(E35:E44) -> 1 | G33: Média total: | H33: =SUM(E33,I33)/2 -> 0.5 | I33: =SUM(G35:G44) -> 0
B34: # | C34: Questão | D34: Resposta do Fornecedor | E34: Resultado | F34: Avaliação BS2 | G34: Resultado SI | H34: Explanação | I34: Evidência | J34: Plano de Ação | K34: Data de Implementação
B35: 1.1 | C35: A empresa processará dados pessoais de colaboradores, clientes finais, não clientes, parceiros de negócios e/ou sócios do grupo BS2, seja de forma direta ou indireta, para a execução do serviço? Em caso afirmativo, listar os dados pessoais que a empresa pretende tratar. | D35: Sim | E35: =IF($D35="Sim",1,IF($D35="Não",0,IF($D35="N/A","-"))) -> 1 | G35: =IF($F35="Não atende",0,IF($F35="Atende parcialmente",1,IF($F35="Atende",2,IF($F35="N/A","-")))) -> FALSE
B36: 1.2 | C36: A empresa designou um Encarregado/DPO ou responsável pela privacidade de dados? Caso afirmativo, favor fornecer os dados de contato, incluindo nome, e-mail, telefone e cargo. | E36: =IF($D36="Sim",1,IF($D36="Não",0,IF($D36="N/A","-"))) -> FALSE | G36: =IF($F36="Não atende",0,IF($F36="Atende parcialmente",1,IF($F36="Atende",2,IF($F36="N/A","-")))) -> FALSE
B37: 1.3 | C37: Existe uma Política de Privacidade atualizada nos últimos 12 meses, aprovada pela administração? Se sim, por favor, disponibilize-a. | E37: =IF($D37="Sim",1,IF($D37="Não",0,IF($D37="N/A","-"))) -> FALSE | G37: =IF($F37="Não atende",0,IF($F37="Atende parcialmente",1,IF($F37="Atende",2,IF($F37="N/A","-")))) -> FALSE
B38: 1.4 | C38: Qual é o tipo de relação de compartilhamento de dados previsto entre a empresa e o Grupo BS2? Por favor, detalhe informando os dados envolvidos e a forma de compartilhamento. | D38: 4 - Não enviará nem receberá dados do BS2 | E38: =IF($D38="Sim",1,IF($D38="Não",0,IF($D38="N/A","-"))) -> FALSE | G38: =IF($F38="Não atende",0,IF($F38="Atende parcialmente",1,IF($F38="Atende",2,IF($F38="N/A","-")))) -> FALSE
B39: 1.5 | C39: A empresa armazenará dados pessoais em países fora do Brasil? Em caso afirmativo, favor listar os dados e indicar os países onde serão armazenados. | E39: =IF($D39="Sim",1,IF($D39="Não",0,IF($D39="N/A","-"))) -> FALSE | G39: =IF($F39="Não atende",0,IF($F39="Atende parcialmente",1,IF($F39="Atende",2,IF($F39="N/A","-")))) -> FALSE
B40: 1.6 | C40: Os dados pessoais coletados serão transferidos internacionalmente para ou recebidos de outros países além do Brasil? Se sim, por favor, liste os dados e indique os países envolvidos na transferência. | E40: =IF($D40="Sim",1,IF($D40="Não",0,IF($D40="N/A","-"))) -> FALSE | G40: =IF($F40="Não atende",0,IF($F40="Atende parcialmente",1,IF($F40="Atende",2,IF($F40="N/A","-")))) -> FALSE
B41: 1.7 | C41: A solução/serviço a ser contratado(a) envolve o tratamento de dados pessoais de crianças e adolescentes? Em caso afirmativo, é obtido o consentimento do responsável legal pela criança e/ou adolescente? | E41: =IF($D41="Sim",1,IF($D41="Não",0,IF($D41="N/A","-"))) -> FALSE | G41: =IF($F41="Não atende",0,IF($F41="Atende parcialmente",1,IF($F41="Atende",2,IF($F41="N/A","-")))) -> FALSE
B42: 1.8 | C42: A solução/serviço a ser contratado(a) inclui o tratamento de dados pessoais sensíveis (como dados de saúde, raça, etnia, religião, política, etc.)? Favor listar os tipos de dados, o propósito do tratamento, a base legal para esse tratamento e as medidas de segurança conforme o artigo 11 da LGPD. | E42: =IF($D42="Sim",1,IF($D42="Não",0,IF($D42="N/A","-"))) -> FALSE | G42: =IF($F42="Não atende",0,IF($F42="Atende parcialmente",1,IF($F42="Atende",2,IF($F42="N/A","-")))) -> FALSE
B43: 1.9 | C43: Para a prestação dos serviços ao Grupo BS2, está prevista a subcontratação de outras empresas ou pessoas autônomas com acesso aos dados? Em caso positivo, descreva as empresas subcontratadas, o escopo de suas atividades no serviço prestado ao Grupo BS2, os dados que terão acesso e o tipo de tratamento realizado. | E43: =IF($D43="Sim",1,IF($D43="Não",0,IF($D43="N/A","-"))) -> FALSE | G43: =IF($F43="Não atende",0,IF($F43="Atende parcialmente",1,IF($F43="Atende",2,IF($F43="N/A","-")))) -> FALSE
B44: 1.10 | C44: Existe um software ou ferramenta ao qual transitará os dados? Se sim descreva o nome. | E44: =IF($D44="Sim",1,IF($D44="Não",0,IF($D44="N/A","-"))) -> FALSE | G44: =IF($F44="Não atende",0,IF($F44="Atende parcialmente",1,IF($F44="Atende",2,IF($F44="N/A","-")))) -> FALSE
B46: 2. Segurança da Informação | E46: =SUM(E48:E58) -> 0 | G46: Média total: | H46: =SUM(E46,I46)/2 -> 0 | I46: =SUM(G48:G58) -> 0
B47: # | C47: Questão | D47: Resposta do Fornecedor | E47: Resultado | F47: Avaliação BS2 | G47: Resultado SI | H47: Explanação | I47: Evidência | J47: Plano de Ação | K47: Data de Implementação
B48: 2.1 | C48: A empresa possui certificação de segurança, como a ISO 27001, ou outra compatível, como SOx, PCI, Bacen, entre outras? Caso positivo, solicitamos o envio do documento comprobatório. | E48: =IF($D48="Sim",1,IF($D48="Não",0,IF($D48="N/A","-"))) -> FALSE | G48: =IF($F48="Não atende",0,IF($F48="Atende parcialmente",1,IF($F48="Atende",2,IF($F48="N/A","-")))) -> FALSE
...

Sheet Lista
B2: SELECIONE | C2: SELECIONE | E2: SELECIONE | G2: SELECIONE | I2: SELECIONE
B3: Pessoas Fisicas | C3: Fisica | E3: Sim | G3: Ate 500 | I3: Dados sensiveis: ( religiao, politica, orientação sexual)
B4: Pessoas Juridicas | C4: Juridica | E4: Não | G4: Até 1.000 | I4: Dados simples: (nome, CPF, RG, telefones, endereços CEPS)
B5: Ambos | C5: Ambas | G5: De 1.000 a 5.000 | I5: Dados financeiros:(dados de conta bancária; informação salarial;)
B6: N/A | C6: N/A | G6: De 5.000 a 10.000 | I6: Dados de saude: (exames;tipo sanguinio; patologias, afins)
G7: De 10.000 a 20.000 | I7: Dados de cartão de credito
G8: De 20.000 a 50.000
G9: De 50.000 a 100.000
G10: De 100.000 a 500.000
G11: De 500.000 a 1 Milhao
G12: Acima de 1 Milhao
I14: SELECIONE
I15: Clientes /parceiros comerciais da ADIQ
I16: Funcionários Adiq
I17: Patrocinadores
I18: Outros( explique no campo ao lado)
I22: SELECIONE
I23: Brasil
I24: Fora do Brasil (explique qual país)
I25: N/A

Sheet Pontuação
B2: Avaliação do fornecedor
B3: Nome do Fornecedor | C3: =Questionário!$D$7 -> 0
B4: Descrição do serviço contratado | C4: =Questionário!$D$16 -> 0
B5: Resultado da Avaliação | C5: =IF(E29<0.49,"Não Recomendado - Risco critico",IF(E29<=0.5,"Recomendado com Ressalva - Risco alto",IF(E29<=1,"Recomendado - Risco médio",IF(E29>=1.1,"Recomendado - Risco baixo")))) -> #REF!
B6: Parecer da Segurança da Informação
B8: Resultado da Avaliação
B9: Itens | C9: Fornecedor | D9: Segurança da Informação | E9: Média total
B10: Sobre a estrutura da empresa
B11: =Questionário!$B$33 -> 1. Privacidade de Dados | C11: =SUM(Questionário!$E$35:$E$45)/20 -> 0.05 | D11: =SUM(Questionário!$G$35:$G$45)/20 -> 0 | E11: =($C11+$D11)/2 -> 0.025
B12: =Questionário!$B$46 -> 2. Segurança da Informação | C12: =SUM(Questionário!$E$48:$E$58)/5 -> 0 | D12: =SUM(Questionário!$G$48:$G$58)/5 -> 0 | E12: =($C12+$D12)/2 -> 0
B13: =Questionário!$B$60 -> 3. Arquitetura de Segurança | C13: =SUM(Questionário!$E$89:$E$97)/7 -> 0 | D13: =SUM(Questionário!$G$89:$G$97)/7 -> 0 | E13: =($C13+$D13)/2 -> 0
B14: =Questionário!$B$99 -> 4. InfraEstrutura | C14: =SUM(Questionário!$E$101:$E$113)/13 -> 0 | D14: =SUM(Questionário!$G$101:$G$113)/13 -> 0 | E14: =($C14+$D14)/2 -> 0
B15: 5. Resolução do Banco Central do Brasil CMN nº 4.893 | C15: =SUM(Questionário!$E$117:$E$121)/4 -> 0 | D15: =SUM(Questionário!$G$117:$G$121)/4 -> 0 | E15: =($C15+$D15)/2 -> 0
B16: =Questionário!#REF! -> #REF! | C16: =SUM(Questionário!#REF!)/3 -> #REF! | D16: =SUM(Questionário!#REF!)/3 -> #REF! | E16: =($C16+$D16)/2 -> #REF!
B17: =Questionário!#REF! -> #REF! | C17: =SUM(Questionário!#REF!)/3 -> #REF! | D17: =SUM(Questionário!#REF!)/3 -> #REF! | E17: =($C17+$D17)/2 -> #REF!
B18: =Questionário!#REF! -> #REF! | C18: =SUM(Questionário!#REF!)/7 -> #REF! | D18: =SUM(Questionário!#REF!)/7 -> #REF! | E18: =($C18+$D18)/2 -> #REF!
B19: =Questionário!#REF! -> #REF! | C19: =SUM(Questionário!#REF!)/21 -> #REF! | D19: =SUM(Questionário!#REF!)/21 -> #REF! | E19: =($C19+$D19)/2 -> #REF!
B20: =Questionário!#REF! -> #REF! | C20: =SUM(Questionário!#REF!)/7 -> #REF! | D20: =SUM(Questionário!#REF!)/7 -> #REF! | E20: =($C20+$D20)/2 -> #REF!
B21: =Questionário!#REF! -> #REF! | C21: =SUM(Questionário!#REF!)/5 -> #REF! | D21: =SUM(Questionário!#REF!)/5 -> #REF! | E21: =($C21+$D21)/2 -> #REF!
B22: =Questionário!#REF! -> #REF! | C22: =SUM(Questionário!#REF!)/14 -> #REF! | D22: =SUM(Questionário!#REF!)/14 -> #REF! | E22: =($C22+$D22)/2 -> #REF!
B23: Sobre a Solução/Ferramenta/Serviço
B24: =Questionário!#REF! -> #REF! | C24: =SUM(Questionário!#REF!)/13 -> #REF! | D24: =SUM(Questionário!#REF!)/13 -> #REF! | E24: =($C24+$D24)/2 -> #REF!
B25: =Questionário!#REF! -> #REF! | C25: =SUM(Questionário!#REF!)/5 -> #REF! | D25: =SUM(Questionário!#REF!)/5 -> #REF! | E25: =($C25+$D25)/2 -> #REF!
B26: =Questionário!#REF! -> #REF! | C26: =SUM(Questionário!#REF!)/6 -> #REF! | D26: =SUM(Questionário!#REF!)/6 -> #REF! | E26: =($C26+$D26)/2 -> #REF!
B27: =Questionário!#REF! -> #REF! | C27: =SUM(Questionário!#REF!)/4 -> #REF! | D27: =SUM(Questionário!#REF!)/4 -> #REF! | E27: =($C27+$D27)/2 -> #REF!
B28: =Questionário!#REF! -> #REF! | C28: =SUM(Questionário!#REF!)/11 -> #REF! | D28: =SUM(Questionário!#REF!)/11 -> #REF! | E28: =($C28+$D28)/2 -> #REF!
B29: Total | E29: =SUM(E11:E28)/17 -> #REF!
B32: Score de Avaliação do Questionário | D32: Pontuação
B33: Recomendado - Risco Baixo | C33: 1,00 - 1,50 | D33: Risco Baixo
B34: Recomendado Com Ressalva - Risco Médio | C34: 0,50 - 0,99 | D34: Risco Médio
B35: Não Recomendado - Risco Alto / Critico | C35: 0,00 - 0,49 | D35: Risco Alto / Critico
B38: Score de Avaliação de Security scorecard | D38: Pontuação | E38: Pontuação Obtida | F38: Risco
B39: Scorecard >= 90 | C39: Acrescenta 0,50 | D39: Risco Baixo | F39: =IF(E40=0.5,"Risco Baixo",IF(E40=0.25,"Risco Médio",IF(E40=-0.5,"Risco alto/Crítico","N/A"))) -> N/A
B40: Scorecard >= 86 a 89 | C40: Acrescenta 0,25 | D40: Risco Médio | E40: N/A
B41: Scorecard <= 85 | C41: Diminui da pontuação acima 0,50 | D41: Risco Alto/ Critico

Sheet Gráfico
B2: Itens de Segurança | C2: Não atende | D2: Atende parcialmente | E2: Atende | F2: N/A | G2: Total
B3: 1. Política | C3: =COUNTIF(Questionário!$F$34:$F$43,Gráfico!$C2) -> 0 | D3: =COUNTIF(Questionário!$F$34:$F$43,Gráfico!$D2) -> 0 | E3: =COUNTIF(Questionário!$F$34:$F$43,Gráfico!$E2) -> 0 | F3: =COUNTIF(Questionário!$F$34:$F$43,Gráfico!$F2) -> 0 | G3: =SUM($C3:$F3) -> 0
B4: 2. Conscientização | C4: =COUNTIF(Questionário!$F$48:$F$56,Gráfico!$C2) -> 0 | D4: =COUNTIF(Questionário!$F$48:$F$56,Gráfico!$D2) -> 0 | E4: =COUNTIF(Questionário!$F$48:$F$56,Gráfico!$E2) -> 0 | F4: =COUNTIF(Questionário!$F$48:$F$56,Gráfico!$F2) -> 0 | G4: =SUM($C4:$F4) -> 0
B5: 3. Vulnerabilidades | C5: =COUNTIF(Questionário!$F$89:$F$89,Gráfico!$C2) -> 0 | D5: =COUNTIF(Questionário!$F$89:$F$89,Gráfico!$D2) -> 0 | E5: =COUNTIF(Questionário!$F$89:$F$89,Gráfico!$E2) -> 0 | F5: =COUNTIF(Questionário!$F$89:$F$89,Gráfico!$F2) -> 0 | G5: =SUM($C5:$F5) -> 0
B6: 4. Desenvolvimento Seguro | C6: =COUNTIF(Questionário!$F$101:$F$113,Gráfico!$C2) -> 0 | D6: =COUNTIF(Questionário!$F$101:$F$113,Gráfico!$D2) -> 0 | E6: =COUNTIF(Questionário!$F$101:$F$113,Gráfico!$E2) -> 0 | F6: =COUNTIF(Questionário!$F$101:$F$113,Gráfico!$F2) -> 0 | G6: =SUM($C6:$F6) -> 0
B7: 5. Incidentes | C7: =COUNTIF(Questionário!$F$117:$F$121,Gráfico!$C2) -> 0 | D7: =COUNTIF(Questionário!$F$117:$F$121,Gráfico!$D2) -> 0 | E7: =COUNTIF(Questionário!$F$117:$F$121,Gráfico!$E2) -> 0 | F7: =COUNTIF(Questionário!$F$117:$F$121,Gráfico!$F2) -> 0 | G7: =SUM($C7:$F7) -> 0
A15: \
